2024-02-01 11:45:43.812552 >>> {command: get_health}
2024-02-01 11:45:43.839622 <<< {isError: false, response: {status: ok}, type: _extensionType, method: ext.flutter.driver}
2024-02-01 11:45:43.841329 >>> {command: request_data, timeout: 1200000}
2024-02-01 11:45:43.983286 <<< {isError: false, response: {message: {"result":"false","failureDetails":["{\"methodName\":\"failing test example\",\"details\":\"══╡ EXCEPTION CAUGHT BY FLUTTER TEST FRAMEWORK ╞═════════════════\\nThe following TestFailure was thrown running a test:\\nExpected: <5>\\n  Actual: <4>\\n\\nWhen the exception was thrown, this was the stack:\\n#4      main.<anonymous closure> (file:///Users/anthonydade/Documents/testEnviornment/flutter_clean_test/flutter_clean_test/integration_test/test.dart:8:5)\\n#5      testWidgets.<anonymous closure>.<anonymous closure> (package:flutter_test/src/widget_tester.dart:168:29)\\n<asynchronous suspension>\\n#6      TestWidgetsFlutterBinding._runTestBody (package:flutter_test/src/binding.dart:1013:5)\\n<asynchronous suspension>\\n#7      TestWidgetsFlutterBinding._createTestCompletionHandler.<anonymous closure> (package:flutter_test/src/binding.dart:804:12)\\n<asynchronous suspension>\\n\\nThis was caught by the test expectation on the following line:\\n  file:///Users/anthonydade/Documents/testEnviornment/flutter_clean_test/flutter_clean_test/integration_test/test.dart line 8\\nThe test description was:\\n  failing test example\\n═════════════════════════════════════════════════════════════════\\n\"}"]}}, type: _extensionType, method: ext.flutter.driver}
